Traceback (most recent call last):
  File "c:\users\25166122m\anaconda3\lib\site-packages\jupyter_cache\executors\utils.py", line 56, in single_nb_execution
    record_timing=False,
  File "c:\users\25166122m\anaconda3\lib\site-packages\nbclient\client.py", line 1077, in execute
    return NotebookClient(nb=nb, resources=resources, km=km, **kwargs).execute()
  File "c:\users\25166122m\anaconda3\lib\site-packages\nbclient\util.py", line 74, in wrapped
    return just_run(coro(*args, **kwargs))
  File "c:\users\25166122m\anaconda3\lib\site-packages\nbclient\util.py", line 53, in just_run
    return loop.run_until_complete(coro)
  File "c:\users\25166122m\anaconda3\lib\asyncio\base_events.py", line 583, in run_until_complete
    return future.result()
  File "c:\users\25166122m\anaconda3\lib\site-packages\nbclient\client.py", line 527, in async_execute
    cell, index, execution_count=self.code_cells_executed + 1
  File "c:\users\25166122m\anaconda3\lib\site-packages\nbclient\client.py", line 822, in async_execute_cell
    self._check_raise_for_error(cell, exec_reply)
  File "c:\users\25166122m\anaconda3\lib\site-packages\nbclient\client.py", line 730, in _check_raise_for_error
    raise CellExecutionError.from_cell_and_msg(cell, exec_reply['content'])
nbclient.exceptions.CellExecutionError: An error occurred while executing the following cell:
------------------
# Simple static display

modelNode=slicer.modules.models.logic().AddModel(slicernb.localPath("data/ProstateMeanShape.stl"))
modelNode
------------------

[0;31m---------------------------------------------------------------------------[0m
[0;31mIndexError[0m                                Traceback (most recent call last)
In  [0;34m[16][0m:
Line [0;34m3[0m:     

File [0;34mC:\Users\25166122M\AppData\Roaming\NA-MIC\Extensions-29370\SlicerJupyter\lib\Slicer-4.11\qt-scripted-modules\JupyterNotebooksLib\files.py[0m, in [0;32mlocalPath[0m:
Line [0;34m79[0m:    notebookDir = os.path.dirname(notebookPath())

File [0;34mC:\Users\25166122M\AppData\Roaming\NA-MIC\Extensions-29370\SlicerJupyter\lib\Slicer-4.11\qt-scripted-modules\JupyterNotebooksLib\files.py[0m, in [0;32mnotebookPath[0m:
Line [0;34m141[0m:   kernel_id = connection_file.split([33m'[39;49;00m[33m-[39;49;00m[33m'[39;49;00m, [34m1[39;49;00m)[[34m1[39;49;00m].split([33m'[39;49;00m[33m.[39;49;00m[33m'[39;49;00m)[[34m0[39;49;00m]

[0;31mIndexError[0m: list index out of range
[0;31m---------------------------------------------------------------------------[0m
IndexError: list index out of range

