Traceback (most recent call last):
  File "/home/aotal/anaconda3/lib/python3.8/site-packages/jupyter_cache/executors/utils.py", line 51, in single_nb_execution
    executenb(
  File "/home/aotal/anaconda3/lib/python3.8/site-packages/nbclient/client.py", line 1107, in execute
    return NotebookClient(nb=nb, resources=resources, km=km, **kwargs).execute()
  File "/home/aotal/anaconda3/lib/python3.8/site-packages/nbclient/util.py", line 74, in wrapped
    return just_run(coro(*args, **kwargs))
  File "/home/aotal/anaconda3/lib/python3.8/site-packages/nbclient/util.py", line 53, in just_run
    return loop.run_until_complete(coro)
  File "/home/aotal/anaconda3/lib/python3.8/asyncio/base_events.py", line 616, in run_until_complete
    return future.result()
  File "/home/aotal/anaconda3/lib/python3.8/site-packages/nbclient/client.py", line 553, in async_execute
    await self.async_execute_cell(
  File "/home/aotal/anaconda3/lib/python3.8/site-packages/nbclient/client.py", line 852, in async_execute_cell
    self._check_raise_for_error(cell, exec_reply)
  File "/home/aotal/anaconda3/lib/python3.8/site-packages/nbclient/client.py", line 760, in _check_raise_for_error
    raise CellExecutionError.from_cell_and_msg(cell, exec_reply_content)
nbclient.exceptions.CellExecutionError: An error occurred while executing the following cell:
------------------
# Simple static display

modelNode=slicer.modules.models.logic().AddModel(slicernb.localPath("data/ProstateMeanShape.stl"))
modelNode
------------------

[0;31m---------------------------------------------------------------------------[0m
[0;31mIndexError[0m                                Traceback (most recent call last)
In  [0;34m[16][0m:
Line [0;34m3[0m:     

File [0;34m/home/aotal/.config/NA-MIC/Extensions-29402/SlicerJupyter/lib/Slicer-4.11/qt-scripted-modules/JupyterNotebooksLib/files.py[0m, in [0;32mlocalPath[0m:
Line [0;34m79[0m:    notebookDir = os.path.dirname(notebookPath())

File [0;34m/home/aotal/.config/NA-MIC/Extensions-29402/SlicerJupyter/lib/Slicer-4.11/qt-scripted-modules/JupyterNotebooksLib/files.py[0m, in [0;32mnotebookPath[0m:
Line [0;34m141[0m:   kernel_id = connection_file.split([33m'[39;49;00m[33m-[39;49;00m[33m'[39;49;00m, [34m1[39;49;00m)[[34m1[39;49;00m].split([33m'[39;49;00m[33m.[39;49;00m[33m'[39;49;00m)[[34m0[39;49;00m]

[0;31mIndexError[0m: list index out of range
[0;31m---------------------------------------------------------------------------[0m
IndexError: list index out of range

