Traceback (most recent call last):
  File "/home/aotal/anaconda3/lib/python3.8/site-packages/jupyter_cache/executors/utils.py", line 51, in single_nb_execution
    executenb(
  File "/home/aotal/anaconda3/lib/python3.8/site-packages/nbclient/client.py", line 1107, in execute
    return NotebookClient(nb=nb, resources=resources, km=km, **kwargs).execute()
  File "/home/aotal/anaconda3/lib/python3.8/site-packages/nbclient/util.py", line 74, in wrapped
    return just_run(coro(*args, **kwargs))
  File "/home/aotal/anaconda3/lib/python3.8/site-packages/nbclient/util.py", line 53, in just_run
    return loop.run_until_complete(coro)
  File "/home/aotal/anaconda3/lib/python3.8/asyncio/base_events.py", line 616, in run_until_complete
    return future.result()
  File "/home/aotal/anaconda3/lib/python3.8/site-packages/nbclient/client.py", line 553, in async_execute
    await self.async_execute_cell(
  File "/home/aotal/anaconda3/lib/python3.8/site-packages/nbclient/client.py", line 852, in async_execute_cell
    self._check_raise_for_error(cell, exec_reply)
  File "/home/aotal/anaconda3/lib/python3.8/site-packages/nbclient/client.py", line 760, in _check_raise_for_error
    raise CellExecutionError.from_cell_and_msg(cell, exec_reply_content)
nbclient.exceptions.CellExecutionError: An error occurred while executing the following cell:
------------------
# Run this cell to load a file from a URL.
# You can load your own data by changing inputs of downloadFromURL.
# Any questions? Write us on the Slicer forum: https://discourse.slicer.org
# Run this cell (Shift+Enter) to show application here
import JupyterNotebooksLib as slicernb
slicernb.AppWindow(contents='full')
slicer.mrmlScene.Clear()
volume = slicernb.downloadFromURL(
    uris="https://github.com/Slicer/SlicerTestingData/releases/download/MD5/39b01631b7b38232a220007230624c8e",
    fileNames="MRHead.nrrd",
    nodeNames="Volume")[0]

slicernb.showVolumeRendering(volume)
------------------

[0;31m---------------------------------------------------------------------------[0m
[0;31mTypeError[0m                                 Traceback (most recent call last)
In  [0;34m[1][0m:
Line [0;34m11[0m:    

[0;31mTypeError[0m: 'MRMLCorePython.vtkMRMLScalarVolumeNode' object is not subscriptable
[0;31m---------------------------------------------------------------------------[0m
TypeError: 'MRMLCorePython.vtkMRMLScalarVolumeNode' object is not subscriptable

